{"level":"ERROR","location":"[<lambda>:1663] data_ws","message":"[SSL: CERTIFICATE_VERIFY_FAILED] certificate verify failed: unable to get local issuer certificate (_ssl.c:1000)","timestamp":"2024-07-07 15:04:27,658+0530","service":"FyersDataSocket"}
{"level":"ERROR","location":"[on_open:1519] data_ws","message":"FyersDataSocket.subscribe() got an unexpected keyword argument 'symbol'","timestamp":"2024-07-07 15:04:29,497+0530","service":"FyersDataSocket","exception":"Traceback (most recent call last):\n  File \"/Library/Frameworks/Python.framework/Versions/3.12/lib/python3.12/site-packages/fyers_apiv3/FyersWebsocket/data_ws.py\", line 1517, in on_open\n    self.OnOpen()\n  File \"/Users/vadhiedhar/Desktop/Trading-App/FyresLogin.py\", line 161, in onopen\n    fyers.subscribe(symbol=symbols, data_type=data_type)\nTypeError: FyersDataSocket.subscribe() got an unexpected keyword argument 'symbol'","exception_name":"TypeError"}
{"level":"ERROR","location":"[on_open:1520] data_ws","message":"FyersDataSocket.subscribe() got an unexpected keyword argument 'symbol'","timestamp":"2024-07-07 15:04:29,504+0530","service":"FyersDataSocket"}
{"level":"ERROR","location":"[<lambda>:1663] data_ws","message":"[SSL: CERTIFICATE_VERIFY_FAILED] certificate verify failed: unable to get local issuer certificate (_ssl.c:1000)","timestamp":"2024-07-07 15:04:32,719+0530","service":"FyersDataSocket"}
{"level":"ERROR","location":"[on_open:1519] data_ws","message":"FyersDataSocket.subscribe() got an unexpected keyword argument 'symbol'","timestamp":"2024-07-07 15:04:34,670+0530","service":"FyersDataSocket","exception":"Traceback (most recent call last):\n  File \"/Library/Frameworks/Python.framework/Versions/3.12/lib/python3.12/site-packages/websocket/_app.py\", line 412, in setSock\n    self.sock.connect(\n  File \"/Library/Frameworks/Python.framework/Versions/3.12/lib/python3.12/site-packages/websocket/_core.py\", line 249, in connect\n    self.sock, addrs = connect(url, self.sock_opt, proxy_info(**options),\n                       ^^^^^^^^^^^^^^^^^^^^^^^^^^^^^^^^^^^^^^^^^^^^^^^^^^\n  File \"/Library/Frameworks/Python.framework/Versions/3.12/lib/python3.12/site-packages/websocket/_http.py\", line 136, in connect\n    sock = _ssl_socket(sock, options.sslopt, hostname)\n           ^^^^^^^^^^^^^^^^^^^^^^^^^^^^^^^^^^^^^^^^^^^\n  File \"/Library/Frameworks/Python.framework/Versions/3.12/lib/python3.12/site-packages/websocket/_http.py\", line 271, in _ssl_socket\n    sock = _wrap_sni_socket(sock, sslopt, hostname, check_hostname)\n           ^^^^^^^^^^^^^^^^^^^^^^^^^^^^^^^^^^^^^^^^^^^^^^^^^^^^^^^^\n  File \"/Library/Frameworks/Python.framework/Versions/3.12/lib/python3.12/site-packages/websocket/_http.py\", line 247, in _wrap_sni_socket\n    return context.wrap_socket(\n           ^^^^^^^^^^^^^^^^^^^^\n  File \"/Library/Frameworks/Python.framework/Versions/3.12/lib/python3.12/ssl.py\", line 455, in wrap_socket\n    return self.sslsocket_class._create(\n           ^^^^^^^^^^^^^^^^^^^^^^^^^^^^^\n  File \"/Library/Frameworks/Python.framework/Versions/3.12/lib/python3.12/ssl.py\", line 1042, in _create\n    self.do_handshake()\n  File \"/Library/Frameworks/Python.framework/Versions/3.12/lib/python3.12/ssl.py\", line 1320, in do_handshake\n    self._sslobj.do_handshake()\nssl.SSLCertVerificationError: [SSL: CERTIFICATE_VERIFY_FAILED] certificate verify failed: unable to get local issuer certificate (_ssl.c:1000)\n\nDuring handling of the above exception, another exception occurred:\n\nTraceback (most recent call last):\n  File \"/Library/Frameworks/Python.framework/Versions/3.12/lib/python3.12/site-packages/fyers_apiv3/FyersWebsocket/data_ws.py\", line 1517, in on_open\n    self.OnOpen()\n  File \"/Users/vadhiedhar/Desktop/Trading-App/FyresLogin.py\", line 161, in onopen\n    fyers.subscribe(symbol=symbols, data_type=data_type)\nTypeError: FyersDataSocket.subscribe() got an unexpected keyword argument 'symbol'","exception_name":"TypeError"}
{"level":"ERROR","location":"[on_open:1520] data_ws","message":"FyersDataSocket.subscribe() got an unexpected keyword argument 'symbol'","timestamp":"2024-07-07 15:04:34,679+0530","service":"FyersDataSocket"}
{"level":"ERROR","location":"[<lambda>:1663] data_ws","message":"[SSL: CERTIFICATE_VERIFY_FAILED] certificate verify failed: unable to get local issuer certificate (_ssl.c:1000)","timestamp":"2024-07-07 15:04:37,776+0530","service":"FyersDataSocket"}
{"level":"ERROR","location":"[on_open:1519] data_ws","message":"FyersDataSocket.subscribe() got an unexpected keyword argument 'symbol'","timestamp":"2024-07-07 15:04:39,731+0530","service":"FyersDataSocket","exception":"Traceback (most recent call last):\n  File \"/Library/Frameworks/Python.framework/Versions/3.12/lib/python3.12/site-packages/websocket/_app.py\", line 412, in setSock\n    self.sock.connect(\n  File \"/Library/Frameworks/Python.framework/Versions/3.12/lib/python3.12/site-packages/websocket/_core.py\", line 249, in connect\n    self.sock, addrs = connect(url, self.sock_opt, proxy_info(**options),\n                       ^^^^^^^^^^^^^^^^^^^^^^^^^^^^^^^^^^^^^^^^^^^^^^^^^^\n  File \"/Library/Frameworks/Python.framework/Versions/3.12/lib/python3.12/site-packages/websocket/_http.py\", line 136, in connect\n    sock = _ssl_socket(sock, options.sslopt, hostname)\n           ^^^^^^^^^^^^^^^^^^^^^^^^^^^^^^^^^^^^^^^^^^^\n  File \"/Library/Frameworks/Python.framework/Versions/3.12/lib/python3.12/site-packages/websocket/_http.py\", line 271, in _ssl_socket\n    sock = _wrap_sni_socket(sock, sslopt, hostname, check_hostname)\n           ^^^^^^^^^^^^^^^^^^^^^^^^^^^^^^^^^^^^^^^^^^^^^^^^^^^^^^^^\n  File \"/Library/Frameworks/Python.framework/Versions/3.12/lib/python3.12/site-packages/websocket/_http.py\", line 247, in _wrap_sni_socket\n    return context.wrap_socket(\n           ^^^^^^^^^^^^^^^^^^^^\n  File \"/Library/Frameworks/Python.framework/Versions/3.12/lib/python3.12/ssl.py\", line 455, in wrap_socket\n    return self.sslsocket_class._create(\n           ^^^^^^^^^^^^^^^^^^^^^^^^^^^^^\n  File \"/Library/Frameworks/Python.framework/Versions/3.12/lib/python3.12/ssl.py\", line 1042, in _create\n    self.do_handshake()\n  File \"/Library/Frameworks/Python.framework/Versions/3.12/lib/python3.12/ssl.py\", line 1320, in do_handshake\n    self._sslobj.do_handshake()\nssl.SSLCertVerificationError: [SSL: CERTIFICATE_VERIFY_FAILED] certificate verify failed: unable to get local issuer certificate (_ssl.c:1000)\n\nDuring handling of the above exception, another exception occurred:\n\nTraceback (most recent call last):\n  File \"/Library/Frameworks/Python.framework/Versions/3.12/lib/python3.12/site-packages/fyers_apiv3/FyersWebsocket/data_ws.py\", line 1517, in on_open\n    self.OnOpen()\n  File \"/Users/vadhiedhar/Desktop/Trading-App/FyresLogin.py\", line 161, in onopen\n    fyers.subscribe(symbol=symbols, data_type=data_type)\nTypeError: FyersDataSocket.subscribe() got an unexpected keyword argument 'symbol'","exception_name":"TypeError"}
{"level":"ERROR","location":"[on_open:1520] data_ws","message":"FyersDataSocket.subscribe() got an unexpected keyword argument 'symbol'","timestamp":"2024-07-07 15:04:39,735+0530","service":"FyersDataSocket"}
{"level":"ERROR","location":"[<lambda>:1663] data_ws","message":"[SSL: CERTIFICATE_VERIFY_FAILED] certificate verify failed: unable to get local issuer certificate (_ssl.c:1000)","timestamp":"2024-07-07 15:04:42,856+0530","service":"FyersDataSocket"}
{"level":"ERROR","location":"[on_open:1519] data_ws","message":"FyersDataSocket.subscribe() got an unexpected keyword argument 'symbol'","timestamp":"2024-07-07 15:04:44,788+0530","service":"FyersDataSocket","exception":"Traceback (most recent call last):\n  File \"/Library/Frameworks/Python.framework/Versions/3.12/lib/python3.12/site-packages/websocket/_app.py\", line 412, in setSock\n    self.sock.connect(\n  File \"/Library/Frameworks/Python.framework/Versions/3.12/lib/python3.12/site-packages/websocket/_core.py\", line 249, in connect\n    self.sock, addrs = connect(url, self.sock_opt, proxy_info(**options),\n                       ^^^^^^^^^^^^^^^^^^^^^^^^^^^^^^^^^^^^^^^^^^^^^^^^^^\n  File \"/Library/Frameworks/Python.framework/Versions/3.12/lib/python3.12/site-packages/websocket/_http.py\", line 136, in connect\n    sock = _ssl_socket(sock, options.sslopt, hostname)\n           ^^^^^^^^^^^^^^^^^^^^^^^^^^^^^^^^^^^^^^^^^^^\n  File \"/Library/Frameworks/Python.framework/Versions/3.12/lib/python3.12/site-packages/websocket/_http.py\", line 271, in _ssl_socket\n    sock = _wrap_sni_socket(sock, sslopt, hostname, check_hostname)\n           ^^^^^^^^^^^^^^^^^^^^^^^^^^^^^^^^^^^^^^^^^^^^^^^^^^^^^^^^\n  File \"/Library/Frameworks/Python.framework/Versions/3.12/lib/python3.12/site-packages/websocket/_http.py\", line 247, in _wrap_sni_socket\n    return context.wrap_socket(\n           ^^^^^^^^^^^^^^^^^^^^\n  File \"/Library/Frameworks/Python.framework/Versions/3.12/lib/python3.12/ssl.py\", line 455, in wrap_socket\n    return self.sslsocket_class._create(\n           ^^^^^^^^^^^^^^^^^^^^^^^^^^^^^\n  File \"/Library/Frameworks/Python.framework/Versions/3.12/lib/python3.12/ssl.py\", line 1042, in _create\n    self.do_handshake()\n  File \"/Library/Frameworks/Python.framework/Versions/3.12/lib/python3.12/ssl.py\", line 1320, in do_handshake\n    self._sslobj.do_handshake()\nssl.SSLCertVerificationError: [SSL: CERTIFICATE_VERIFY_FAILED] certificate verify failed: unable to get local issuer certificate (_ssl.c:1000)\n\nDuring handling of the above exception, another exception occurred:\n\nTraceback (most recent call last):\n  File \"/Library/Frameworks/Python.framework/Versions/3.12/lib/python3.12/site-packages/fyers_apiv3/FyersWebsocket/data_ws.py\", line 1517, in on_open\n    self.OnOpen()\n  File \"/Users/vadhiedhar/Desktop/Trading-App/FyresLogin.py\", line 161, in onopen\n    fyers.subscribe(symbol=symbols, data_type=data_type)\nTypeError: FyersDataSocket.subscribe() got an unexpected keyword argument 'symbol'","exception_name":"TypeError"}
{"level":"ERROR","location":"[on_open:1520] data_ws","message":"FyersDataSocket.subscribe() got an unexpected keyword argument 'symbol'","timestamp":"2024-07-07 15:04:44,792+0530","service":"FyersDataSocket"}
{"level":"ERROR","location":"[<lambda>:1663] data_ws","message":"[SSL: CERTIFICATE_VERIFY_FAILED] certificate verify failed: unable to get local issuer certificate (_ssl.c:1000)","timestamp":"2024-07-07 15:04:47,919+0530","service":"FyersDataSocket"}
{"level":"ERROR","location":"[on_open:1519] data_ws","message":"FyersDataSocket.subscribe() got an unexpected keyword argument 'symbol'","timestamp":"2024-07-07 15:04:49,868+0530","service":"FyersDataSocket","exception":"Traceback (most recent call last):\n  File \"/Library/Frameworks/Python.framework/Versions/3.12/lib/python3.12/site-packages/websocket/_app.py\", line 412, in setSock\n    self.sock.connect(\n  File \"/Library/Frameworks/Python.framework/Versions/3.12/lib/python3.12/site-packages/websocket/_core.py\", line 249, in connect\n    self.sock, addrs = connect(url, self.sock_opt, proxy_info(**options),\n                       ^^^^^^^^^^^^^^^^^^^^^^^^^^^^^^^^^^^^^^^^^^^^^^^^^^\n  File \"/Library/Frameworks/Python.framework/Versions/3.12/lib/python3.12/site-packages/websocket/_http.py\", line 136, in connect\n    sock = _ssl_socket(sock, options.sslopt, hostname)\n           ^^^^^^^^^^^^^^^^^^^^^^^^^^^^^^^^^^^^^^^^^^^\n  File \"/Library/Frameworks/Python.framework/Versions/3.12/lib/python3.12/site-packages/websocket/_http.py\", line 271, in _ssl_socket\n    sock = _wrap_sni_socket(sock, sslopt, hostname, check_hostname)\n           ^^^^^^^^^^^^^^^^^^^^^^^^^^^^^^^^^^^^^^^^^^^^^^^^^^^^^^^^\n  File \"/Library/Frameworks/Python.framework/Versions/3.12/lib/python3.12/site-packages/websocket/_http.py\", line 247, in _wrap_sni_socket\n    return context.wrap_socket(\n           ^^^^^^^^^^^^^^^^^^^^\n  File \"/Library/Frameworks/Python.framework/Versions/3.12/lib/python3.12/ssl.py\", line 455, in wrap_socket\n    return self.sslsocket_class._create(\n           ^^^^^^^^^^^^^^^^^^^^^^^^^^^^^\n  File \"/Library/Frameworks/Python.framework/Versions/3.12/lib/python3.12/ssl.py\", line 1042, in _create\n    self.do_handshake()\n  File \"/Library/Frameworks/Python.framework/Versions/3.12/lib/python3.12/ssl.py\", line 1320, in do_handshake\n    self._sslobj.do_handshake()\nssl.SSLCertVerificationError: [SSL: CERTIFICATE_VERIFY_FAILED] certificate verify failed: unable to get local issuer certificate (_ssl.c:1000)\n\nDuring handling of the above exception, another exception occurred:\n\nTraceback (most recent call last):\n  File \"/Library/Frameworks/Python.framework/Versions/3.12/lib/python3.12/site-packages/fyers_apiv3/FyersWebsocket/data_ws.py\", line 1517, in on_open\n    self.OnOpen()\n  File \"/Users/vadhiedhar/Desktop/Trading-App/FyresLogin.py\", line 161, in onopen\n    fyers.subscribe(symbol=symbols, data_type=data_type)\nTypeError: FyersDataSocket.subscribe() got an unexpected keyword argument 'symbol'","exception_name":"TypeError"}
{"level":"ERROR","location":"[on_open:1520] data_ws","message":"FyersDataSocket.subscribe() got an unexpected keyword argument 'symbol'","timestamp":"2024-07-07 15:04:49,871+0530","service":"FyersDataSocket"}
{"level":"ERROR","location":"[<lambda>:1663] data_ws","message":"[SSL: CERTIFICATE_VERIFY_FAILED] certificate verify failed: unable to get local issuer certificate (_ssl.c:1000)","timestamp":"2024-07-07 15:04:52,994+0530","service":"FyersDataSocket"}
{"level":"ERROR","location":"[on_open:1519] data_ws","message":"FyersDataSocket.subscribe() got an unexpected keyword argument 'symbol'","timestamp":"2024-07-07 15:04:54,931+0530","service":"FyersDataSocket","exception":"Traceback (most recent call last):\n  File \"/Library/Frameworks/Python.framework/Versions/3.12/lib/python3.12/site-packages/websocket/_app.py\", line 412, in setSock\n    self.sock.connect(\n  File \"/Library/Frameworks/Python.framework/Versions/3.12/lib/python3.12/site-packages/websocket/_core.py\", line 249, in connect\n    self.sock, addrs = connect(url, self.sock_opt, proxy_info(**options),\n                       ^^^^^^^^^^^^^^^^^^^^^^^^^^^^^^^^^^^^^^^^^^^^^^^^^^\n  File \"/Library/Frameworks/Python.framework/Versions/3.12/lib/python3.12/site-packages/websocket/_http.py\", line 136, in connect\n    sock = _ssl_socket(sock, options.sslopt, hostname)\n           ^^^^^^^^^^^^^^^^^^^^^^^^^^^^^^^^^^^^^^^^^^^\n  File \"/Library/Frameworks/Python.framework/Versions/3.12/lib/python3.12/site-packages/websocket/_http.py\", line 271, in _ssl_socket\n    sock = _wrap_sni_socket(sock, sslopt, hostname, check_hostname)\n           ^^^^^^^^^^^^^^^^^^^^^^^^^^^^^^^^^^^^^^^^^^^^^^^^^^^^^^^^\n  File \"/Library/Frameworks/Python.framework/Versions/3.12/lib/python3.12/site-packages/websocket/_http.py\", line 247, in _wrap_sni_socket\n    return context.wrap_socket(\n           ^^^^^^^^^^^^^^^^^^^^\n  File \"/Library/Frameworks/Python.framework/Versions/3.12/lib/python3.12/ssl.py\", line 455, in wrap_socket\n    return self.sslsocket_class._create(\n           ^^^^^^^^^^^^^^^^^^^^^^^^^^^^^\n  File \"/Library/Frameworks/Python.framework/Versions/3.12/lib/python3.12/ssl.py\", line 1042, in _create\n    self.do_handshake()\n  File \"/Library/Frameworks/Python.framework/Versions/3.12/lib/python3.12/ssl.py\", line 1320, in do_handshake\n    self._sslobj.do_handshake()\nssl.SSLCertVerificationError: [SSL: CERTIFICATE_VERIFY_FAILED] certificate verify failed: unable to get local issuer certificate (_ssl.c:1000)\n\nDuring handling of the above exception, another exception occurred:\n\nTraceback (most recent call last):\n  File \"/Library/Frameworks/Python.framework/Versions/3.12/lib/python3.12/site-packages/fyers_apiv3/FyersWebsocket/data_ws.py\", line 1517, in on_open\n    self.OnOpen()\n  File \"/Users/vadhiedhar/Desktop/Trading-App/FyresLogin.py\", line 161, in onopen\n    fyers.subscribe(symbol=symbols, data_type=data_type)\nTypeError: FyersDataSocket.subscribe() got an unexpected keyword argument 'symbol'","exception_name":"TypeError"}
{"level":"ERROR","location":"[on_open:1520] data_ws","message":"FyersDataSocket.subscribe() got an unexpected keyword argument 'symbol'","timestamp":"2024-07-07 15:04:54,935+0530","service":"FyersDataSocket"}
{"level":"ERROR","location":"[<lambda>:1663] data_ws","message":"[SSL: CERTIFICATE_VERIFY_FAILED] certificate verify failed: unable to get local issuer certificate (_ssl.c:1000)","timestamp":"2024-07-07 15:05:03,072+0530","service":"FyersDataSocket"}
{"level":"ERROR","location":"[on_open:1519] data_ws","message":"FyersDataSocket.subscribe() got an unexpected keyword argument 'symbol'","timestamp":"2024-07-07 15:05:05,006+0530","service":"FyersDataSocket","exception":"Traceback (most recent call last):\n  File \"/Library/Frameworks/Python.framework/Versions/3.12/lib/python3.12/site-packages/websocket/_app.py\", line 412, in setSock\n    self.sock.connect(\n  File \"/Library/Frameworks/Python.framework/Versions/3.12/lib/python3.12/site-packages/websocket/_core.py\", line 249, in connect\n    self.sock, addrs = connect(url, self.sock_opt, proxy_info(**options),\n                       ^^^^^^^^^^^^^^^^^^^^^^^^^^^^^^^^^^^^^^^^^^^^^^^^^^\n  File \"/Library/Frameworks/Python.framework/Versions/3.12/lib/python3.12/site-packages/websocket/_http.py\", line 136, in connect\n    sock = _ssl_socket(sock, options.sslopt, hostname)\n           ^^^^^^^^^^^^^^^^^^^^^^^^^^^^^^^^^^^^^^^^^^^\n  File \"/Library/Frameworks/Python.framework/Versions/3.12/lib/python3.12/site-packages/websocket/_http.py\", line 271, in _ssl_socket\n    sock = _wrap_sni_socket(sock, sslopt, hostname, check_hostname)\n           ^^^^^^^^^^^^^^^^^^^^^^^^^^^^^^^^^^^^^^^^^^^^^^^^^^^^^^^^\n  File \"/Library/Frameworks/Python.framework/Versions/3.12/lib/python3.12/site-packages/websocket/_http.py\", line 247, in _wrap_sni_socket\n    return context.wrap_socket(\n           ^^^^^^^^^^^^^^^^^^^^\n  File \"/Library/Frameworks/Python.framework/Versions/3.12/lib/python3.12/ssl.py\", line 455, in wrap_socket\n    return self.sslsocket_class._create(\n           ^^^^^^^^^^^^^^^^^^^^^^^^^^^^^\n  File \"/Library/Frameworks/Python.framework/Versions/3.12/lib/python3.12/ssl.py\", line 1042, in _create\n    self.do_handshake()\n  File \"/Library/Frameworks/Python.framework/Versions/3.12/lib/python3.12/ssl.py\", line 1320, in do_handshake\n    self._sslobj.do_handshake()\nssl.SSLCertVerificationError: [SSL: CERTIFICATE_VERIFY_FAILED] certificate verify failed: unable to get local issuer certificate (_ssl.c:1000)\n\nDuring handling of the above exception, another exception occurred:\n\nTraceback (most recent call last):\n  File \"/Library/Frameworks/Python.framework/Versions/3.12/lib/python3.12/site-packages/fyers_apiv3/FyersWebsocket/data_ws.py\", line 1517, in on_open\n    self.OnOpen()\n  File \"/Users/vadhiedhar/Desktop/Trading-App/FyresLogin.py\", line 161, in onopen\n    fyers.subscribe(symbol=symbols, data_type=data_type)\nTypeError: FyersDataSocket.subscribe() got an unexpected keyword argument 'symbol'","exception_name":"TypeError"}
{"level":"ERROR","location":"[on_open:1520] data_ws","message":"FyersDataSocket.subscribe() got an unexpected keyword argument 'symbol'","timestamp":"2024-07-07 15:05:05,009+0530","service":"FyersDataSocket"}
{"level":"ERROR","location":"[<lambda>:1663] data_ws","message":"[SSL: CERTIFICATE_VERIFY_FAILED] certificate verify failed: unable to get local issuer certificate (_ssl.c:1000)","timestamp":"2024-07-07 15:05:13,141+0530","service":"FyersDataSocket"}
{"level":"ERROR","location":"[on_open:1519] data_ws","message":"FyersDataSocket.subscribe() got an unexpected keyword argument 'symbol'","timestamp":"2024-07-07 15:05:15,082+0530","service":"FyersDataSocket","exception":"Traceback (most recent call last):\n  File \"/Library/Frameworks/Python.framework/Versions/3.12/lib/python3.12/site-packages/websocket/_app.py\", line 412, in setSock\n    self.sock.connect(\n  File \"/Library/Frameworks/Python.framework/Versions/3.12/lib/python3.12/site-packages/websocket/_core.py\", line 249, in connect\n    self.sock, addrs = connect(url, self.sock_opt, proxy_info(**options),\n                       ^^^^^^^^^^^^^^^^^^^^^^^^^^^^^^^^^^^^^^^^^^^^^^^^^^\n  File \"/Library/Frameworks/Python.framework/Versions/3.12/lib/python3.12/site-packages/websocket/_http.py\", line 136, in connect\n    sock = _ssl_socket(sock, options.sslopt, hostname)\n           ^^^^^^^^^^^^^^^^^^^^^^^^^^^^^^^^^^^^^^^^^^^\n  File \"/Library/Frameworks/Python.framework/Versions/3.12/lib/python3.12/site-packages/websocket/_http.py\", line 271, in _ssl_socket\n    sock = _wrap_sni_socket(sock, sslopt, hostname, check_hostname)\n           ^^^^^^^^^^^^^^^^^^^^^^^^^^^^^^^^^^^^^^^^^^^^^^^^^^^^^^^^\n  File \"/Library/Frameworks/Python.framework/Versions/3.12/lib/python3.12/site-packages/websocket/_http.py\", line 247, in _wrap_sni_socket\n    return context.wrap_socket(\n           ^^^^^^^^^^^^^^^^^^^^\n  File \"/Library/Frameworks/Python.framework/Versions/3.12/lib/python3.12/ssl.py\", line 455, in wrap_socket\n    return self.sslsocket_class._create(\n           ^^^^^^^^^^^^^^^^^^^^^^^^^^^^^\n  File \"/Library/Frameworks/Python.framework/Versions/3.12/lib/python3.12/ssl.py\", line 1042, in _create\n    self.do_handshake()\n  File \"/Library/Frameworks/Python.framework/Versions/3.12/lib/python3.12/ssl.py\", line 1320, in do_handshake\n    self._sslobj.do_handshake()\nssl.SSLCertVerificationError: [SSL: CERTIFICATE_VERIFY_FAILED] certificate verify failed: unable to get local issuer certificate (_ssl.c:1000)\n\nDuring handling of the above exception, another exception occurred:\n\nTraceback (most recent call last):\n  File \"/Library/Frameworks/Python.framework/Versions/3.12/lib/python3.12/site-packages/fyers_apiv3/FyersWebsocket/data_ws.py\", line 1517, in on_open\n    self.OnOpen()\n  File \"/Users/vadhiedhar/Desktop/Trading-App/FyresLogin.py\", line 161, in onopen\n    fyers.subscribe(symbol=symbols, data_type=data_type)\nTypeError: FyersDataSocket.subscribe() got an unexpected keyword argument 'symbol'","exception_name":"TypeError"}
{"level":"ERROR","location":"[on_open:1520] data_ws","message":"FyersDataSocket.subscribe() got an unexpected keyword argument 'symbol'","timestamp":"2024-07-07 15:05:15,085+0530","service":"FyersDataSocket"}
{"level":"ERROR","location":"[<lambda>:1663] data_ws","message":"[SSL: CERTIFICATE_VERIFY_FAILED] certificate verify failed: unable to get local issuer certificate (_ssl.c:1000)","timestamp":"2024-07-07 15:05:23,203+0530","service":"FyersDataSocket"}
{"level":"ERROR","location":"[on_open:1519] data_ws","message":"FyersDataSocket.subscribe() got an unexpected keyword argument 'symbol'","timestamp":"2024-07-07 15:05:25,152+0530","service":"FyersDataSocket","exception":"Traceback (most recent call last):\n  File \"/Library/Frameworks/Python.framework/Versions/3.12/lib/python3.12/site-packages/websocket/_app.py\", line 412, in setSock\n    self.sock.connect(\n  File \"/Library/Frameworks/Python.framework/Versions/3.12/lib/python3.12/site-packages/websocket/_core.py\", line 249, in connect\n    self.sock, addrs = connect(url, self.sock_opt, proxy_info(**options),\n                       ^^^^^^^^^^^^^^^^^^^^^^^^^^^^^^^^^^^^^^^^^^^^^^^^^^\n  File \"/Library/Frameworks/Python.framework/Versions/3.12/lib/python3.12/site-packages/websocket/_http.py\", line 136, in connect\n    sock = _ssl_socket(sock, options.sslopt, hostname)\n           ^^^^^^^^^^^^^^^^^^^^^^^^^^^^^^^^^^^^^^^^^^^\n  File \"/Library/Frameworks/Python.framework/Versions/3.12/lib/python3.12/site-packages/websocket/_http.py\", line 271, in _ssl_socket\n    sock = _wrap_sni_socket(sock, sslopt, hostname, check_hostname)\n           ^^^^^^^^^^^^^^^^^^^^^^^^^^^^^^^^^^^^^^^^^^^^^^^^^^^^^^^^\n  File \"/Library/Frameworks/Python.framework/Versions/3.12/lib/python3.12/site-packages/websocket/_http.py\", line 247, in _wrap_sni_socket\n    return context.wrap_socket(\n           ^^^^^^^^^^^^^^^^^^^^\n  File \"/Library/Frameworks/Python.framework/Versions/3.12/lib/python3.12/ssl.py\", line 455, in wrap_socket\n    return self.sslsocket_class._create(\n           ^^^^^^^^^^^^^^^^^^^^^^^^^^^^^\n  File \"/Library/Frameworks/Python.framework/Versions/3.12/lib/python3.12/ssl.py\", line 1042, in _create\n    self.do_handshake()\n  File \"/Library/Frameworks/Python.framework/Versions/3.12/lib/python3.12/ssl.py\", line 1320, in do_handshake\n    self._sslobj.do_handshake()\nssl.SSLCertVerificationError: [SSL: CERTIFICATE_VERIFY_FAILED] certificate verify failed: unable to get local issuer certificate (_ssl.c:1000)\n\nDuring handling of the above exception, another exception occurred:\n\nTraceback (most recent call last):\n  File \"/Library/Frameworks/Python.framework/Versions/3.12/lib/python3.12/site-packages/fyers_apiv3/FyersWebsocket/data_ws.py\", line 1517, in on_open\n    self.OnOpen()\n  File \"/Users/vadhiedhar/Desktop/Trading-App/FyresLogin.py\", line 161, in onopen\n    fyers.subscribe(symbol=symbols, data_type=data_type)\nTypeError: FyersDataSocket.subscribe() got an unexpected keyword argument 'symbol'","exception_name":"TypeError"}
{"level":"ERROR","location":"[on_open:1520] data_ws","message":"FyersDataSocket.subscribe() got an unexpected keyword argument 'symbol'","timestamp":"2024-07-07 15:05:25,156+0530","service":"FyersDataSocket"}
{"level":"ERROR","location":"[<lambda>:1663] data_ws","message":"[SSL: CERTIFICATE_VERIFY_FAILED] certificate verify failed: unable to get local issuer certificate (_ssl.c:1000)","timestamp":"2024-07-07 15:05:33,277+0530","service":"FyersDataSocket"}
{"level":"ERROR","location":"[on_open:1519] data_ws","message":"FyersDataSocket.subscribe() got an unexpected keyword argument 'symbol'","timestamp":"2024-07-07 15:05:35,216+0530","service":"FyersDataSocket","exception":"Traceback (most recent call last):\n  File \"/Library/Frameworks/Python.framework/Versions/3.12/lib/python3.12/site-packages/websocket/_app.py\", line 412, in setSock\n    self.sock.connect(\n  File \"/Library/Frameworks/Python.framework/Versions/3.12/lib/python3.12/site-packages/websocket/_core.py\", line 249, in connect\n    self.sock, addrs = connect(url, self.sock_opt, proxy_info(**options),\n                       ^^^^^^^^^^^^^^^^^^^^^^^^^^^^^^^^^^^^^^^^^^^^^^^^^^\n  File \"/Library/Frameworks/Python.framework/Versions/3.12/lib/python3.12/site-packages/websocket/_http.py\", line 136, in connect\n    sock = _ssl_socket(sock, options.sslopt, hostname)\n           ^^^^^^^^^^^^^^^^^^^^^^^^^^^^^^^^^^^^^^^^^^^\n  File \"/Library/Frameworks/Python.framework/Versions/3.12/lib/python3.12/site-packages/websocket/_http.py\", line 271, in _ssl_socket\n    sock = _wrap_sni_socket(sock, sslopt, hostname, check_hostname)\n           ^^^^^^^^^^^^^^^^^^^^^^^^^^^^^^^^^^^^^^^^^^^^^^^^^^^^^^^^\n  File \"/Library/Frameworks/Python.framework/Versions/3.12/lib/python3.12/site-packages/websocket/_http.py\", line 247, in _wrap_sni_socket\n    return context.wrap_socket(\n           ^^^^^^^^^^^^^^^^^^^^\n  File \"/Library/Frameworks/Python.framework/Versions/3.12/lib/python3.12/ssl.py\", line 455, in wrap_socket\n    return self.sslsocket_class._create(\n           ^^^^^^^^^^^^^^^^^^^^^^^^^^^^^\n  File \"/Library/Frameworks/Python.framework/Versions/3.12/lib/python3.12/ssl.py\", line 1042, in _create\n    self.do_handshake()\n  File \"/Library/Frameworks/Python.framework/Versions/3.12/lib/python3.12/ssl.py\", line 1320, in do_handshake\n    self._sslobj.do_handshake()\nssl.SSLCertVerificationError: [SSL: CERTIFICATE_VERIFY_FAILED] certificate verify failed: unable to get local issuer certificate (_ssl.c:1000)\n\nDuring handling of the above exception, another exception occurred:\n\nTraceback (most recent call last):\n  File \"/Library/Frameworks/Python.framework/Versions/3.12/lib/python3.12/site-packages/fyers_apiv3/FyersWebsocket/data_ws.py\", line 1517, in on_open\n    self.OnOpen()\n  File \"/Users/vadhiedhar/Desktop/Trading-App/FyresLogin.py\", line 161, in onopen\n    fyers.subscribe(symbol=symbols, data_type=data_type)\nTypeError: FyersDataSocket.subscribe() got an unexpected keyword argument 'symbol'","exception_name":"TypeError"}
{"level":"ERROR","location":"[on_open:1520] data_ws","message":"FyersDataSocket.subscribe() got an unexpected keyword argument 'symbol'","timestamp":"2024-07-07 15:05:35,219+0530","service":"FyersDataSocket"}
{"level":"ERROR","location":"[<lambda>:1663] data_ws","message":"[SSL: CERTIFICATE_VERIFY_FAILED] certificate verify failed: unable to get local issuer certificate (_ssl.c:1000)","timestamp":"2024-07-07 15:05:43,340+0530","service":"FyersDataSocket"}
{"level":"ERROR","location":"[on_open:1519] data_ws","message":"FyersDataSocket.subscribe() got an unexpected keyword argument 'symbol'","timestamp":"2024-07-07 15:05:45,288+0530","service":"FyersDataSocket","exception":"Traceback (most recent call last):\n  File \"/Library/Frameworks/Python.framework/Versions/3.12/lib/python3.12/site-packages/websocket/_app.py\", line 412, in setSock\n    self.sock.connect(\n  File \"/Library/Frameworks/Python.framework/Versions/3.12/lib/python3.12/site-packages/websocket/_core.py\", line 249, in connect\n    self.sock, addrs = connect(url, self.sock_opt, proxy_info(**options),\n                       ^^^^^^^^^^^^^^^^^^^^^^^^^^^^^^^^^^^^^^^^^^^^^^^^^^\n  File \"/Library/Frameworks/Python.framework/Versions/3.12/lib/python3.12/site-packages/websocket/_http.py\", line 136, in connect\n    sock = _ssl_socket(sock, options.sslopt, hostname)\n           ^^^^^^^^^^^^^^^^^^^^^^^^^^^^^^^^^^^^^^^^^^^\n  File \"/Library/Frameworks/Python.framework/Versions/3.12/lib/python3.12/site-packages/websocket/_http.py\", line 271, in _ssl_socket\n    sock = _wrap_sni_socket(sock, sslopt, hostname, check_hostname)\n           ^^^^^^^^^^^^^^^^^^^^^^^^^^^^^^^^^^^^^^^^^^^^^^^^^^^^^^^^\n  File \"/Library/Frameworks/Python.framework/Versions/3.12/lib/python3.12/site-packages/websocket/_http.py\", line 247, in _wrap_sni_socket\n    return context.wrap_socket(\n           ^^^^^^^^^^^^^^^^^^^^\n  File \"/Library/Frameworks/Python.framework/Versions/3.12/lib/python3.12/ssl.py\", line 455, in wrap_socket\n    return self.sslsocket_class._create(\n           ^^^^^^^^^^^^^^^^^^^^^^^^^^^^^\n  File \"/Library/Frameworks/Python.framework/Versions/3.12/lib/python3.12/ssl.py\", line 1042, in _create\n    self.do_handshake()\n  File \"/Library/Frameworks/Python.framework/Versions/3.12/lib/python3.12/ssl.py\", line 1320, in do_handshake\n    self._sslobj.do_handshake()\nssl.SSLCertVerificationError: [SSL: CERTIFICATE_VERIFY_FAILED] certificate verify failed: unable to get local issuer certificate (_ssl.c:1000)\n\nDuring handling of the above exception, another exception occurred:\n\nTraceback (most recent call last):\n  File \"/Library/Frameworks/Python.framework/Versions/3.12/lib/python3.12/site-packages/fyers_apiv3/FyersWebsocket/data_ws.py\", line 1517, in on_open\n    self.OnOpen()\n  File \"/Users/vadhiedhar/Desktop/Trading-App/FyresLogin.py\", line 161, in onopen\n    fyers.subscribe(symbol=symbols, data_type=data_type)\nTypeError: FyersDataSocket.subscribe() got an unexpected keyword argument 'symbol'","exception_name":"TypeError"}
{"level":"ERROR","location":"[on_open:1520] data_ws","message":"FyersDataSocket.subscribe() got an unexpected keyword argument 'symbol'","timestamp":"2024-07-07 15:05:45,292+0530","service":"FyersDataSocket"}
